File: data/Tautona-quartzite-triaxial-v2.txt
Sig1	Sig2	Sig3
212.7	20	20
217	20	20
338.9	20	20
273.3	20	20
261.1	40	40
350.8	40	40
440.3	60	60
387.4	60	60
320.8	60	60
392.3	60	60
467.5	90	90
299	90	90
298.5	90	90
534	120	120
457	120	120
549.3	120	120
439.7	120	120